2019-11-06 21:12:12.879 parsl.dataflow.dflow:83 [DEBUG]  Starting DataFlowKernel with config
Config(
    app_cache=True, 
    checkpoint_files=None, 
    checkpoint_mode=None, 
    checkpoint_period=None, 
    data_management_max_threads=10, 
    executors=[ThreadPoolExecutor(
        label='threads', 
        managed=True, 
        max_threads=2, 
        storage_access=None, 
        thread_name_prefix='', 
        working_dir=None
    )], 
    initialize_logging=True, 
    lazy_errors=True, 
    max_idletime=120.0, 
    monitoring=None, 
    retries=0, 
    run_dir='runinfo', 
    strategy='simple', 
    usage_tracking=False
)
2019-11-06 21:12:12.879 parsl.dataflow.dflow:84 [INFO]  Parsl version: 0.9.0
2019-11-06 21:12:12.879 parsl.dataflow.usage_tracking.usage:126 [DEBUG]  Tracking status: False
2019-11-06 21:12:12.879 parsl.dataflow.usage_tracking.usage:127 [DEBUG]  Testing mode   : False
2019-11-06 21:12:12.879 parsl.dataflow.dflow:110 [INFO]  Run id is: 443cb224-66c4-4582-8f3c-0291a8559dc7
2019-11-06 21:12:12.988 parsl.dataflow.memoization:52 [INFO]  App caching initialized
2019-11-06 21:12:12.988 parsl.dataflow.strategy:125 [DEBUG]  Scaling strategy: simple
2019-11-06 21:12:13.143 parsl.dataflow.dflow:484 [DEBUG]  Adding output dependencies
2019-11-06 21:12:13.143 parsl.dataflow.dflow:708 [INFO]  Task 0 submitted for App fun_df, waiting on tasks []
2019-11-06 21:12:13.143 parsl.dataflow.dflow:714 [DEBUG]  Task 0 set to pending state with AppFuture: <AppFuture super=<AppFuture at 0x7f02ef40bd68 state=pending>>
2019-11-06 21:12:13.144 parsl.dataflow.dflow:452 [INFO]  Task 0 launched on executor threads
2019-11-06 21:12:13.144 parsl.app.errors:158 [DEBUG]  Reraising exception of type <class 'TypeError'>
2019-11-06 21:12:13.144 parsl.dataflow.dflow:257 [DEBUG]  Task 0 failed
2019-11-06 21:12:13.144 parsl.dataflow.dflow:279 [ERROR]  Task 0 failed after 0 retry attempts
Traceback (most recent call last):
  File "/home/kalpani/.local/lib/python3.5/site-packages/parsl/dataflow/dflow.py", line 254, in handle_exec_update
    res.reraise()
  File "/home/kalpani/.local/lib/python3.5/site-packages/parsl/app/errors.py", line 163, in reraise
    reraise(t, v, tb)
  File "/home/kalpani/.local/lib/python3.5/site-packages/six.py", line 692, in reraise
    raise value.with_traceback(tb)
  File "/home/kalpani/.local/lib/python3.5/site-packages/parsl/app/errors.py", line 172, in wrapper
    return func(*args, **kwargs)
TypeError: fun_df() missing 1 required positional argument: 'i'
2019-11-06 21:12:13.145 parsl.app.errors:158 [DEBUG]  Reraising exception of type <class 'TypeError'>
2019-11-06 21:12:13.157 parsl.dataflow.dflow:864 [INFO]  DFK cleanup initiated
2019-11-06 21:12:13.157 parsl.dataflow.dflow:750 [INFO]  Summary of tasks in DFK:
2019-11-06 21:12:13.157 parsl.dataflow.dflow:781 [INFO]  Tasks in state States.failed: 0
2019-11-06 21:12:13.157 parsl.dataflow.dflow:788 [INFO]  End of summary
2019-11-06 21:12:13.157 parsl.dataflow.dflow:888 [INFO]  Terminating flow_control and strategy threads
2019-11-06 21:12:13.157 parsl.executors.threads:96 [DEBUG]  Done with executor shutdown
2019-11-06 21:12:13.157 parsl.executors.threads:96 [DEBUG]  Done with executor shutdown
2019-11-06 21:12:13.158 parsl.dataflow.dflow:920 [INFO]  DFK cleanup complete
