2019-11-08 16:36:54.159 parsl.dataflow.dflow:83 [DEBUG]  Starting DataFlowKernel with config
Config(
    app_cache=True, 
    checkpoint_files=None, 
    checkpoint_mode=None, 
    checkpoint_period=None, 
    data_management_max_threads=10, 
    executors=[ThreadPoolExecutor(
        label='threads', 
        managed=True, 
        max_threads=2, 
        storage_access=None, 
        thread_name_prefix='', 
        working_dir=None
    )], 
    initialize_logging=True, 
    lazy_errors=True, 
    max_idletime=120.0, 
    monitoring=None, 
    retries=0, 
    run_dir='runinfo', 
    strategy='simple', 
    usage_tracking=False
)
2019-11-08 16:36:54.159 parsl.dataflow.dflow:84 [INFO]  Parsl version: 0.9.0
2019-11-08 16:36:54.159 parsl.dataflow.usage_tracking.usage:126 [DEBUG]  Tracking status: False
2019-11-08 16:36:54.159 parsl.dataflow.usage_tracking.usage:127 [DEBUG]  Testing mode   : False
2019-11-08 16:36:54.160 parsl.dataflow.dflow:110 [INFO]  Run id is: 4094f4b6-94d1-4a27-b632-f2e4ca61e2dc
2019-11-08 16:36:54.216 parsl.dataflow.memoization:52 [INFO]  App caching initialized
2019-11-08 16:36:54.217 parsl.dataflow.strategy:125 [DEBUG]  Scaling strategy: simple
2019-11-08 16:36:54.218 parsl.dataflow.dflow:484 [DEBUG]  Adding output dependencies
2019-11-08 16:36:54.218 parsl.dataflow.dflow:708 [INFO]  Task 0 submitted for App missingValuesMode, waiting on tasks []
2019-11-08 16:36:54.218 parsl.dataflow.dflow:714 [DEBUG]  Task 0 set to pending state with AppFuture: <AppFuture super=<AppFuture at 0x7fd5e392fc50 state=pending>>
2019-11-08 16:36:54.219 parsl.dataflow.dflow:452 [INFO]  Task 0 launched on executor threads
2019-11-08 16:36:54.581 parsl.app.errors:158 [DEBUG]  Reraising exception of type <class 'statistics.StatisticsError'>
2019-11-08 16:36:54.582 parsl.dataflow.dflow:257 [DEBUG]  Task 0 failed
2019-11-08 16:36:54.582 parsl.dataflow.dflow:279 [ERROR]  Task 0 failed after 0 retry attempts
Traceback (most recent call last):
  File "/home/rajini/.local/lib/python3.5/site-packages/parsl/dataflow/dflow.py", line 254, in handle_exec_update
    res.reraise()
  File "/home/rajini/.local/lib/python3.5/site-packages/parsl/app/errors.py", line 163, in reraise
    reraise(t, v, tb)
  File "/home/rajini/.local/lib/python3.5/site-packages/six.py", line 695, in reraise
    raise value.with_traceback(tb)
  File "/home/rajini/.local/lib/python3.5/site-packages/parsl/app/errors.py", line 172, in wrapper
    return func(*args, **kwargs)
  File "missingValuesMode.py", line 40, in missingValuesMode
    modeOfCol = statistics.mode(df1)
  File "/usr/lib/python3.5/statistics.py", line 477, in mode
    raise StatisticsError('no mode for empty data')
statistics.StatisticsError: no mode for empty data
2019-11-08 16:36:54.583 parsl.app.errors:158 [DEBUG]  Reraising exception of type <class 'statistics.StatisticsError'>
2019-11-08 16:36:54.599 parsl.dataflow.dflow:864 [INFO]  DFK cleanup initiated
2019-11-08 16:36:54.599 parsl.dataflow.dflow:750 [INFO]  Summary of tasks in DFK:
2019-11-08 16:36:54.599 parsl.dataflow.dflow:781 [INFO]  Tasks in state States.failed: 0
2019-11-08 16:36:54.599 parsl.dataflow.dflow:788 [INFO]  End of summary
2019-11-08 16:36:54.599 parsl.dataflow.dflow:888 [INFO]  Terminating flow_control and strategy threads
2019-11-08 16:36:54.600 parsl.executors.threads:96 [DEBUG]  Done with executor shutdown
2019-11-08 16:36:54.600 parsl.executors.threads:96 [DEBUG]  Done with executor shutdown
2019-11-08 16:36:54.600 parsl.dataflow.dflow:920 [INFO]  DFK cleanup complete
