2019-11-08 16:42:36.228 parsl.dataflow.dflow:83 [DEBUG]  Starting DataFlowKernel with config
Config(
    app_cache=True, 
    checkpoint_files=None, 
    checkpoint_mode=None, 
    checkpoint_period=None, 
    data_management_max_threads=10, 
    executors=[ThreadPoolExecutor(
        label='threads', 
        managed=True, 
        max_threads=2, 
        storage_access=None, 
        thread_name_prefix='', 
        working_dir=None
    )], 
    initialize_logging=True, 
    lazy_errors=True, 
    max_idletime=120.0, 
    monitoring=None, 
    retries=0, 
    run_dir='runinfo', 
    strategy='simple', 
    usage_tracking=False
)
2019-11-08 16:42:36.228 parsl.dataflow.dflow:84 [INFO]  Parsl version: 0.9.0
2019-11-08 16:42:36.228 parsl.dataflow.usage_tracking.usage:126 [DEBUG]  Tracking status: False
2019-11-08 16:42:36.228 parsl.dataflow.usage_tracking.usage:127 [DEBUG]  Testing mode   : False
2019-11-08 16:42:36.229 parsl.dataflow.dflow:110 [INFO]  Run id is: afa6305e-3f87-4e16-8b3a-49b78a988413
2019-11-08 16:42:36.290 parsl.dataflow.memoization:52 [INFO]  App caching initialized
2019-11-08 16:42:36.291 parsl.dataflow.strategy:125 [DEBUG]  Scaling strategy: simple
2019-11-08 16:42:36.292 parsl.dataflow.dflow:484 [DEBUG]  Adding output dependencies
2019-11-08 16:42:36.293 parsl.dataflow.dflow:708 [INFO]  Task 0 submitted for App missingValuesMode, waiting on tasks []
2019-11-08 16:42:36.293 parsl.dataflow.dflow:714 [DEBUG]  Task 0 set to pending state with AppFuture: <AppFuture super=<AppFuture at 0x7f67346b1ef0 state=pending>>
2019-11-08 16:42:36.293 parsl.dataflow.dflow:452 [INFO]  Task 0 launched on executor threads
2019-11-08 16:42:36.696 parsl.app.errors:158 [DEBUG]  Reraising exception of type <class 'NameError'>
2019-11-08 16:42:36.697 parsl.dataflow.dflow:257 [DEBUG]  Task 0 failed
2019-11-08 16:42:36.697 parsl.dataflow.dflow:279 [ERROR]  Task 0 failed after 0 retry attempts
Traceback (most recent call last):
  File "/home/rajini/.local/lib/python3.5/site-packages/parsl/dataflow/dflow.py", line 254, in handle_exec_update
    res.reraise()
  File "/home/rajini/.local/lib/python3.5/site-packages/parsl/app/errors.py", line 163, in reraise
    reraise(t, v, tb)
  File "/home/rajini/.local/lib/python3.5/site-packages/six.py", line 695, in reraise
    raise value.with_traceback(tb)
  File "/home/rajini/.local/lib/python3.5/site-packages/parsl/app/errors.py", line 172, in wrapper
    return func(*args, **kwargs)
  File "missingValuesMode.py", line 43, in missingValuesMode
    except StatisticsError:
NameError: name 'StatisticsError' is not defined
2019-11-08 16:42:36.698 parsl.app.errors:158 [DEBUG]  Reraising exception of type <class 'NameError'>
2019-11-08 16:42:36.719 parsl.dataflow.dflow:864 [INFO]  DFK cleanup initiated
2019-11-08 16:42:36.719 parsl.dataflow.dflow:750 [INFO]  Summary of tasks in DFK:
2019-11-08 16:42:36.719 parsl.dataflow.dflow:781 [INFO]  Tasks in state States.failed: 0
2019-11-08 16:42:36.719 parsl.dataflow.dflow:788 [INFO]  End of summary
2019-11-08 16:42:36.720 parsl.dataflow.dflow:888 [INFO]  Terminating flow_control and strategy threads
2019-11-08 16:42:36.720 parsl.executors.threads:96 [DEBUG]  Done with executor shutdown
2019-11-08 16:42:36.720 parsl.executors.threads:96 [DEBUG]  Done with executor shutdown
2019-11-08 16:42:36.721 parsl.dataflow.dflow:920 [INFO]  DFK cleanup complete
