2019-11-08 19:09:52.973 parsl.dataflow.dflow:83 [DEBUG]  Starting DataFlowKernel with config
Config(
    app_cache=True, 
    checkpoint_files=None, 
    checkpoint_mode=None, 
    checkpoint_period=None, 
    data_management_max_threads=10, 
    executors=[ThreadPoolExecutor(
        label='threads', 
        managed=True, 
        max_threads=2, 
        storage_access=None, 
        thread_name_prefix='', 
        working_dir=None
    )], 
    initialize_logging=True, 
    lazy_errors=True, 
    max_idletime=120.0, 
    monitoring=None, 
    retries=0, 
    run_dir='runinfo', 
    strategy='simple', 
    usage_tracking=False
)
2019-11-08 19:09:52.973 parsl.dataflow.dflow:84 [INFO]  Parsl version: 0.9.0
2019-11-08 19:09:52.973 parsl.dataflow.usage_tracking.usage:126 [DEBUG]  Tracking status: False
2019-11-08 19:09:52.973 parsl.dataflow.usage_tracking.usage:127 [DEBUG]  Testing mode   : False
2019-11-08 19:09:52.973 parsl.dataflow.dflow:110 [INFO]  Run id is: 13eeb61c-7f33-4c77-b2d7-d35423a6926e
2019-11-08 19:09:53.057 parsl.dataflow.memoization:52 [INFO]  App caching initialized
2019-11-08 19:09:53.057 parsl.dataflow.strategy:125 [DEBUG]  Scaling strategy: simple
2019-11-08 19:09:53.064 parsl.dataflow.dflow:484 [DEBUG]  Adding output dependencies
2019-11-08 19:09:53.064 parsl.dataflow.dflow:708 [INFO]  Task 0 submitted for App rescale, waiting on tasks []
2019-11-08 19:09:53.064 parsl.dataflow.dflow:714 [DEBUG]  Task 0 set to pending state with AppFuture: <AppFuture super=<AppFuture at 0x7f56126c39e8 state=pending>>
2019-11-08 19:09:53.064 parsl.dataflow.dflow:452 [INFO]  Task 0 launched on executor threads
2019-11-08 19:09:53.065 parsl.app.errors:158 [DEBUG]  Reraising exception of type <class 'UnboundLocalError'>
2019-11-08 19:09:53.065 parsl.dataflow.dflow:257 [DEBUG]  Task 0 failed
2019-11-08 19:09:53.065 parsl.dataflow.dflow:279 [ERROR]  Task 0 failed after 0 retry attempts
Traceback (most recent call last):
  File "/home/kalpani/.local/lib/python3.5/site-packages/parsl/dataflow/dflow.py", line 254, in handle_exec_update
    res.reraise()
  File "/home/kalpani/.local/lib/python3.5/site-packages/parsl/app/errors.py", line 163, in reraise
    reraise(t, v, tb)
  File "/home/kalpani/.local/lib/python3.5/site-packages/six.py", line 692, in reraise
    raise value.with_traceback(tb)
  File "/home/kalpani/.local/lib/python3.5/site-packages/parsl/app/errors.py", line 172, in wrapper
    return func(*args, **kwargs)
  File "rescale.py", line 27, in rescale
    if dataType.dataType(key, df) != "str":
UnboundLocalError: local variable 'df' referenced before assignment
2019-11-08 19:09:53.065 parsl.app.errors:158 [DEBUG]  Reraising exception of type <class 'UnboundLocalError'>
2019-11-08 19:09:53.074 parsl.dataflow.dflow:864 [INFO]  DFK cleanup initiated
2019-11-08 19:09:53.074 parsl.dataflow.dflow:750 [INFO]  Summary of tasks in DFK:
2019-11-08 19:09:53.074 parsl.dataflow.dflow:781 [INFO]  Tasks in state States.failed: 0
2019-11-08 19:09:53.074 parsl.dataflow.dflow:788 [INFO]  End of summary
2019-11-08 19:09:53.075 parsl.dataflow.dflow:888 [INFO]  Terminating flow_control and strategy threads
2019-11-08 19:09:53.075 parsl.executors.threads:96 [DEBUG]  Done with executor shutdown
2019-11-08 19:09:53.075 parsl.executors.threads:96 [DEBUG]  Done with executor shutdown
2019-11-08 19:09:53.075 parsl.dataflow.dflow:920 [INFO]  DFK cleanup complete
